Workbook

Sheet Cover
B5: ✨ PREMIUM BUDGET TRACKER ✨
B6: FY 2026 Edition • Plan • Track • Save • Grow
D8: 📊 OPEN YEARLY DASHBOARD
B12: 📖 HOW TO USE THIS TRACKER
B13: 🔵 | D13: Blue numbers | F13: Editable input cells — type your Planned & Actual amounts here.
B14: ⚫ | D14: Black text | F14: Auto-calculated totals, percentages & formulas — never edit these.
B15: 🟢 | D15: Green highlight | F15: You met or exceeded a goal (income/savings) or stayed within budget.
B16: 🔴 | D16: Red highlight | F16: You've overspent a category — time to review!
B17: 🥇 | D17: Gold accents | F17: Key totals, KPI cards & premium highlights.
B19: 📅 JUMP TO A MONTH
B20: ❄️ January | E20: 💖 February | H20: 🌱 March | K20: 🌧️ April
B22: 🌸 May | E22: ☀️ June | H22: 🌧️ July | K22: 🌻 August
B24: 🍃 September | E24: 🎆 October | H24: 🪔 November | K24: 🎄 December
B27: 💡 Each month is fully self-contained — fill it in independently. The Dashboard pulls everything together automatically.
B28: ✨ Premium Budget Tracker 2026 • Made with 💛 for smarter saving ✨

Sheet Jan
B1: 🏠 DASHBOARD | F1: ✨ PREMIUM MONTHLY BUDGET TRACKER ✨ | N1: ◀ Dashboard | R1: Feb ▶
B2: ❄️ JANUARY
B3: Monthly Budget Tracker • Edit only the blue input cells
B5: 💵 TOTAL INCOME | G5: 🧾 TOTAL EXPENSES | L5: 💎 TOTAL SAVINGS | Q5: ⚖️ NET BALANCE
B7: =G28 -> 72200 | G7: =G31 -> 47074 | L7: =G32 -> 18975 | Q7: =G33 -> 6151
B10: 💵 INCOME | G10: 🏠 FIXED EXPENSES (Bills + EMIs) | L10: 🛍️ VARIABLE EXPENSES | Q10: 💎 SAVINGS & INVESTMENTS
B11: Category | C11: Planned | D11: Actual | E11: Progress | G11: Category | H11: Planned | I11: Actual | J11: Progress | L11: Category | M11: Planned | N11: Actual | O11: Progress | Q11: Category | R11: Planned | S11: Actual | T11: Progress
B12: 💼 Salary / Full-time Job | C12: 65000 | D12: 65000 | E12: =IF(C12=0,IF(D12=0,0,1),D12/C12) -> 1 | G12: 🏠 Rent / Home Loan EMI | H12: 15000 | I12: 15150 | J12: =IF(H12=0,IF(I12=0,0,1),I12/H12) -> 1.01 | L12: 🛒 Groceries | M12: 6000 | N12: 5880 | O12: =IF(M12=0,IF(N12=0,0,1),N12/M12) -> 0.98 | Q12: 🚨 Emergency Fund | R12: 3000 | S12: 3450 | T12: =IF(R12=0,IF(S12=0,0,1),S12/R12) -> 1.15
B13: 🧑‍💻 Freelance / Side Hustle | C13: 6000 | D13: 6000 | E13: =IF(C13=0,IF(D13=0,0,1),D13/C13) -> 1 | G13: 💡 Electricity Bill | H13: 2200 | I13: 2178 | J13: =IF(H13=0,IF(I13=0,0,1),I13/H13) -> 0.99 | L13: 🍽️ Eating Out / Dining | M13: 2500 | N13: 2625 | O13: =IF(M13=0,IF(N13=0,0,1),N13/M13) -> 1.05 | Q13: 📊 Mutual Fund / SIP | R13: 5000 | S13: 5750 | T13: =IF(R13=0,IF(S13=0,0,1),S13/R13) -> 1.15
B14: 🏢 Business Income | C14: 0 | D14: 0 | E14: =IF(C14=0,IF(D14=0,0,1),D14/C14) -> 0 | G14: 🚰 Water Bill | H14: 300 | I14: 308 | J14: =IF(H14=0,IF(I14=0,0,1),I14/H14) -> 1.0266667 | L14: ⛽ Transport / Fuel | M14: 2000 | N14: 2020 | O14: =IF(M14=0,IF(N14=0,0,1),N14/M14) -> 1.01 | Q14: 🏦 PPF / EPF | R14: 2000 | S14: 2300 | T14: =IF(R14=0,IF(S14=0,0,1),S14/R14) -> 1.15
B15: 🏠 Rental Income | C15: 0 | D15: 0 | E15: =IF(C15=0,IF(D15=0,0,1),D15/C15) -> 0 | G15: 🌐 Internet / WiFi | H15: 800 | I15: 804 | J15: =IF(H15=0,IF(I15=0,0,1),I15/H15) -> 1.005 | L15: 🛍️ Shopping / Clothing | M15: 3000 | N15: 2910 | O15: =IF(M15=0,IF(N15=0,0,1),N15/M15) -> 0.97 | Q15: 🥇 Stocks / Gold | R15: 1000 | S15: 1150 | T15: =IF(R15=0,IF(S15=0,0,1),S15/R15) -> 1.15
B16: 📈 Investment Returns | C16: 1200 | D16: 1200 | E16: =IF(C16=0,IF(D16=0,0,1),D16/C16) -> 1 | G16: 📱 Mobile Recharge | H16: 400 | I16: 394 | J16: =IF(H16=0,IF(I16=0,0,1),I16/H16) -> 0.985 | L16: 🎮 Entertainment | M16: 1000 | N16: 1040 | O16: =IF(M16=0,IF(N16=0,0,1),N16/M16) -> 1.04 | Q16: 🔒 Fixed Deposit / RD | R16: 2000 | S16: 2300 | T16: =IF(R16=0,IF(S16=0,0,1),S16/R16) -> 1.15
B17: 🎁 Bonus / Incentive | C17: 0 | D17: 0 | E17: =IF(C17=0,IF(D17=0,0,1),D17/C17) -> 0 | G17: 🛡️ Insurance Premium | H17: 1200 | I17: 1224 | J17: =IF(H17=0,IF(I17=0,0,1),I17/H17) -> 1.02 | L17: 💇 Personal Care | M17: 800 | N17: 800 | O17: =IF(M17=0,IF(N17=0,0,1),N17/M17) -> 1 | Q17: 👴 Retirement (NPS) | R17: 1500 | S17: 1725 | T17: =IF(R17=0,IF(S17=0,0,1),S17/R17) -> 1.15
B18: ➕ Other Income 1 | C18: 0 | D18: 0 | E18: =IF(C18=0,IF(D18=0,0,1),D18/C18) -> 0 | G18: 🚗 Car / Vehicle EMI | H18: 6000 | I18: 6000 | J18: =IF(H18=0,IF(I18=0,0,1),I18/H18) -> 1 | L18: 🏥 Health / Medical | M18: 1000 | N18: 960 | O18: =IF(M18=0,IF(N18=0,0,1),N18/M18) -> 0.96 | Q18: 🎯 Goal-based Savings | R18: 2000 | S18: 2300 | T18: =IF(R18=0,IF(S18=0,0,1),S18/R18) -> 1.15
B19: ➕ Other Income 2 | C19: 0 | D19: 0 | E19: =IF(C19=0,IF(D19=0,0,1),D19/C19) -> 0 | G19: 🎬 OTT Subscriptions | H19: 500 | I19: 490 | J19: =IF(H19=0,IF(I19=0,0,1),I19/H19) -> 0.98 | L19: 📚 Education / Courses | M19: 0 | N19: 0 | O19: =IF(M19=0,IF(N19=0,0,1),N19/M19) -> 0 | Q19: ➕ Other Savings | R19: 0 | S19: 0 | T19: =IF(R19=0,IF(S19=0,0,1),S19/R19) -> 0
B20: TOTAL | C20: =SUM(C12:C19) -> 72200 | D20: =SUM(D12:D19) -> 72200 | E20: =IF(C20=0,IF(D20=0,0,1),D20/C20) -> 1 | G20: 🏢 Society / Maintenance | H20: 1500 | I20: 1522 | J20: =IF(H20=0,IF(I20=0,0,1),I20/H20) -> 1.0146667 | L20: ✈️ Travel / Vacation | M20: 1500 | N20: 1485 | O20: =IF(M20=0,IF(N20=0,0,1),N20/M20) -> 0.99 | Q20: TOTAL | R20: =SUM(R12:R19) -> 16500 | S20: =SUM(S12:S19) -> 18975 | T20: =IF(R20=0,IF(S20=0,0,1),S20/R20) -> 1.15
G21: ➕ Other Fixed Expense | H21: 0 | I21: 0 | J21: =IF(H21=0,IF(I21=0,0,1),I21/H21) -> 0 | L21: 🎀 Gifts & Donations | M21: 600 | N21: 570 | O21: =IF(M21=0,IF(N21=0,0,1),N21/M21) -> 0.95
G22: TOTAL | H22: =SUM(H12:H21) -> 27900 | I22: =SUM(I12:I21) -> 28070 | J22: =IF(H22=0,IF(I22=0,0,1),I22/H22) -> 1.0060932 | L22: 🧺 Household Items | M22: 700 | N22: 714 | O22: =IF(M22=0,IF(N22=0,0,1),N22/M22) -> 1.02
L23: ➕ Other Variable Expense | M23: 0 | N23: 0 | O23: =IF(M23=0,IF(N23=0,0,1),N23/M23) -> 0
L24: TOTAL | M24: =SUM(M12:M23) -> 19100 | N24: =SUM(N12:N23) -> 19004 | O24: =IF(M24=0,IF(N24=0,0,1),N24/M24) -> 0.99497382
B26: 📊 MONTHLY SUMMARY
B27: Metric | F27: Planned | G27: Actual | H27: Status
B28: 💵 Total Income | F28: =C20 -> 72200 | G28: =D20 -> 72200 | H28: =IF(G28>=F28,"✅ Goal Met","⚠️ Below Target") -> ✅ Goal Met
B29: 🏠 Total Fixed Expenses | F29: =H22 -> 27900 | G29: =I22 -> 28070 | H29: =IF(G29>F29,"⚠️ Over Budget","✅ On Budget") -> ⚠️ Over Budget
B30: 🛍️ Total Variable Expenses | F30: =M24 -> 19100 | G30: =N24 -> 19004 | H30: =IF(G30>F30,"⚠️ Over Budget","✅ On Budget") -> ✅ On Budget
B31: 🧾 Total Expenses (Fixed + Variable) | F31: =F29+F30 -> 47000 | G31: =G29+G30 -> 47074 | H31: =IF(G31>F31,"⚠️ Over Budget","✅ On Budget") -> ⚠️ Over Budget
B32: 💎 Total Savings & Investments | F32: =R20 -> 16500 | G32: =S20 -> 18975 | H32: =IF(G32>=F32,"✅ Goal Met","⚠️ Below Goal") -> ✅ Goal Met
B33: ⚖️ Remaining Balance | F33: =F28-F31-F32 -> 8700 | G33: =G28-G31-G32 -> 6151 | H33: =IF(G33>=0,"✅ Surplus","⚠️ Deficit") -> ✅ Surplus
B34: 📈 Savings Rate (Savings ÷ Income) | F34: =IF(F28=0,0,F32/F28) -> 0.22853186 | G34: =IF(G28=0,0,G32/G28) -> 0.26281163 | H34: =IF(G34>=0.2,"🌟 Excellent","👍 Keep Going") -> 🌟 Excellent
B36: 💰 REMAINING BALANCE This Month | G36: =G33 -> 6151 | O36: =IF(G33>=0,"✅ You're on track!","⚠️ You've overspent") -> ✅ You're on track!
B41: 💡 Tip: Blue numbers are editable inputs. Black text & percentages auto-calculate — nothing else needs to be touched.
B42: ✨ Premium Budget Tracker 2026 ✨

Sheet Feb
B1: 🏠 DASHBOARD | F1: ✨ PREMIUM MONTHLY BUDGET TRACKER ✨ | N1: ◀ Jan | R1: Mar ▶
B2: 💖 FEBRUARY
B3: Monthly Budget Tracker • Edit only the blue input cells
B5: 💵 TOTAL INCOME | G5: 🧾 TOTAL EXPENSES | L5: 💎 TOTAL SAVINGS | Q5: ⚖️ NET BALANCE
B7: =G28 -> 72200 | G7: =G31 -> 47267 | L7: =G32 -> 16535 | Q7: =G33 -> 8398
B10: 💵 INCOME | G10: 🏠 FIXED EXPENSES (Bills + EMIs) | L10: 🛍️ VARIABLE EXPENSES | Q10: 💎 SAVINGS & INVESTMENTS
B11: Category | C11: Planned | D11: Actual | E11: Progress | G11: Category | H11: Planned | I11: Actual | J11: Progress | L11: Category | M11: Planned | N11: Actual | O11: Progress | Q11: Category | R11: Planned | S11: Actual | T11: Progress
B12: 💼 Salary / Full-time Job | C12: 65000 | D12: 65000 | E12: =IF(C12=0,IF(D12=0,0,1),D12/C12) -> 1 | G12: 🏠 Rent / Home Loan EMI | H12: 15000 | I12: 15300 | J12: =IF(H12=0,IF(I12=0,0,1),I12/H12) -> 1.02 | L12: 🛒 Groceries | M12: 6000 | N12: 6000 | O12: =IF(M12=0,IF(N12=0,0,1),N12/M12) -> 1 | Q12: 🚨 Emergency Fund | R12: 3000 | S12: 2940 | T12: =IF(R12=0,IF(S12=0,0,1),S12/R12) -> 0.98
B13: 🧑‍💻 Freelance / Side Hustle | C13: 6000 | D13: 6000 | E13: =IF(C13=0,IF(D13=0,0,1),D13/C13) -> 1 | G13: 💡 Electricity Bill | H13: 2200 | I13: 2200 | J13: =IF(H13=0,IF(I13=0,0,1),I13/H13) -> 1 | L13: 🍽️ Eating Out / Dining | M13: 2500 | N13: 2400 | O13: =IF(M13=0,IF(N13=0,0,1),N13/M13) -> 0.96 | Q13: 📊 Mutual Fund / SIP | R13: 5000 | S13: 5075 | T13: =IF(R13=0,IF(S13=0,0,1),S13/R13) -> 1.015
B14: 🏢 Business Income | C14: 0 | D14: 0 | E14: =IF(C14=0,IF(D14=0,0,1),D14/C14) -> 0 | G14: 🚰 Water Bill | H14: 300 | I14: 294 | J14: =IF(H14=0,IF(I14=0,0,1),I14/H14) -> 0.98 | L14: ⛽ Transport / Fuel | M14: 2000 | N14: 2060 | O14: =IF(M14=0,IF(N14=0,0,1),N14/M14) -> 1.03 | Q14: 🏦 PPF / EPF | R14: 2000 | S14: 1990 | T14: =IF(R14=0,IF(S14=0,0,1),S14/R14) -> 0.995
B15: 🏠 Rental Income | C15: 0 | D15: 0 | E15: =IF(C15=0,IF(D15=0,0,1),D15/C15) -> 0 | G15: 🌐 Internet / WiFi | H15: 800 | I15: 812 | J15: =IF(H15=0,IF(I15=0,0,1),I15/H15) -> 1.015 | L15: 🛍️ Shopping / Clothing | M15: 3000 | N15: 2970 | O15: =IF(M15=0,IF(N15=0,0,1),N15/M15) -> 0.99 | Q15: 🥇 Stocks / Gold | R15: 1000 | S15: 975 | T15: =IF(R15=0,IF(S15=0,0,1),S15/R15) -> 0.975
B16: 📈 Investment Returns | C16: 1200 | D16: 1200 | E16: =IF(C16=0,IF(D16=0,0,1),D16/C16) -> 1 | G16: 📱 Mobile Recharge | H16: 400 | I16: 398 | J16: =IF(H16=0,IF(I16=0,0,1),I16/H16) -> 0.995 | L16: 🎮 Entertainment | M16: 1000 | N16: 950 | O16: =IF(M16=0,IF(N16=0,0,1),N16/M16) -> 0.95 | Q16: 🔒 Fixed Deposit / RD | R16: 2000 | S16: 2020 | T16: =IF(R16=0,IF(S16=0,0,1),S16/R16) -> 1.01
B17: 🎁 Bonus / Incentive | C17: 0 | D17: 0 | E17: =IF(C17=0,IF(D17=0,0,1),D17/C17) -> 0 | G17: 🛡️ Insurance Premium | H17: 1200 | I17: 1170 | J17: =IF(H17=0,IF(I17=0,0,1),I17/H17) -> 0.975 | L17: 💇 Personal Care | M17: 800 | N17: 816 | O17: =IF(M17=0,IF(N17=0,0,1),N17/M17) -> 1.02 | Q17: 👴 Retirement (NPS) | R17: 1500 | S17: 1485 | T17: =IF(R17=0,IF(S17=0,0,1),S17/R17) -> 0.99
B18: ➕ Other Income 1 | C18: 0 | D18: 0 | E18: =IF(C18=0,IF(D18=0,0,1),D18/C18) -> 0 | G18: 🚗 Car / Vehicle EMI | H18: 6000 | I18: 6060 | J18: =IF(H18=0,IF(I18=0,0,1),I18/H18) -> 1.01 | L18: 🏥 Health / Medical | M18: 1000 | N18: 980 | O18: =IF(M18=0,IF(N18=0,0,1),N18/M18) -> 0.98 | Q18: 🎯 Goal-based Savings | R18: 2000 | S18: 2050 | T18: =IF(R18=0,IF(S18=0,0,1),S18/R18) -> 1.025
B19: ➕ Other Income 2 | C19: 0 | D19: 0 | E19: =IF(C19=0,IF(D19=0,0,1),D19/C19) -> 0 | G19: 🎬 OTT Subscriptions | H19: 500 | I19: 495 | J19: =IF(H19=0,IF(I19=0,0,1),I19/H19) -> 0.99 | L19: 📚 Education / Courses | M19: 0 | N19: 0 | O19: =IF(M19=0,IF(N19=0,0,1),N19/M19) -> 0 | Q19: ➕ Other Savings | R19: 0 | S19: 0 | T19: =IF(R19=0,IF(S19=0,0,1),S19/R19) -> 0
B20: TOTAL | C20: =SUM(C12:C19) -> 72200 | D20: =SUM(D12:D19) -> 72200 | E20: =IF(C20=0,IF(D20=0,0,1),D20/C20) -> 1 | G20: 🏢 Society / Maintenance | H20: 1500 | I20: 1537 | J20: =IF(H20=0,IF(I20=0,0,1),I20/H20) -> 1.0246667 | L20: ✈️ Travel / Vacation | M20: 1500 | N20: 1515 | O20: =IF(M20=0,IF(N20=0,0,1),N20/M20) -> 1.01 | Q20: TOTAL | R20: =SUM(R12:R19) -> 16500 | S20: =SUM(S12:S19) -> 16535 | T20: =IF(R20=0,IF(S20=0,0,1),S20/R20) -> 1.0021212
G21: ➕ Other Fixed Expense | H21: 0 | I21: 0 | J21: =IF(H21=0,IF(I21=0,0,1),I21/H21) -> 0 | L21: 🎀 Gifts & Donations | M21: 600 | N21: 582 | O21: =IF(M21=0,IF(N21=0,0,1),N21/M21) -> 0.97
G22: TOTAL | H22: =SUM(H12:H21) -> 27900 | I22: =SUM(I12:I21) -> 28266 | J22: =IF(H22=0,IF(I22=0,0,1),I22/H22) -> 1.0131183 | L22: 🧺 Household Items | M22: 700 | N22: 728 | O22: =IF(M22=0,IF(N22=0,0,1),N22/M22) -> 1.04
L23: ➕ Other Variable Expense | M23: 0 | N23: 0 | O23: =IF(M23=0,IF(N23=0,0,1),N23/M23) -> 0
L24: TOTAL | M24: =SUM(M12:M23) -> 19100 | N24: =SUM(N12:N23) -> 19001 | O24: =IF(M24=0,IF(N24=0,0,1),N24/M24) -> 0.99481675
B26: 📊 MONTHLY SUMMARY
B27: Metric | F27: Planned | G27: Actual | H27: Status
B28: 💵 Total Income | F28: =C20 -> 72200 | G28: =D20 -> 72200 | H28: =IF(G28>=F28,"✅ Goal Met","⚠️ Below Target") -> ✅ Goal Met
B29: 🏠 Total Fixed Expenses | F29: =H22 -> 27900 | G29: =I22 -> 28266 | H29: =IF(G29>F29,"⚠️ Over Budget","✅ On Budget") -> ⚠️ Over Budget
B30: 🛍️ Total Variable Expenses | F30: =M24 -> 19100 | G30: =N24 -> 19001 | H30: =IF(G30>F30,"⚠️ Over Budget","✅ On Budget") -> ✅ On Budget
B31: 🧾 Total Expenses (Fixed + Variable) | F31: =F29+F30 -> 47000 | G31: =G29+G30 -> 47267 | H31: =IF(G31>F31,"⚠️ Over Budget","✅ On Budget") -> ⚠️ Over Budget
B32: 💎 Total Savings & Investments | F32: =R20 -> 16500 | G32: =S20 -> 16535 | H32: =IF(G32>=F32,"✅ Goal Met","⚠️ Below Goal") -> ✅ Goal Met
B33: ⚖️ Remaining Balance | F33: =F28-F31-F32 -> 8700 | G33: =G28-G31-G32 -> 8398 | H33: =IF(G33>=0,"✅ Surplus","⚠️ Deficit") -> ✅ Surplus
B34: 📈 Savings Rate (Savings ÷ Income) | F34: =IF(F28=0,0,F32/F28) -> 0.22853186 | G34: =IF(G28=0,0,G32/G28) -> 0.22901662 | H34: =IF(G34>=0.2,"🌟 Excellent","👍 Keep Going") -> 🌟 Excellent
B36: 💰 REMAINING BALANCE This Month | G36: =G33 -> 8398 | O36: =IF(G33>=0,"✅ You're on track!","⚠️ You've overspent") -> ✅ You're on track!
B41: 💡 Tip: Blue numbers are editable inputs. Black text & percentages auto-calculate — nothing else needs to be touched.
B42: ✨ Premium Budget Tracker 2026 ✨

Sheet Mar
B1: 🏠 DASHBOARD | F1: ✨ PREMIUM MONTHLY BUDGET TRACKER ✨ | N1: ◀ Feb | R1: Apr ▶
B2: 🌱 MARCH
B3: Monthly Budget Tracker • Edit only the blue input cells
B5: 💵 TOTAL INCOME | G5: 🧾 TOTAL EXPENSES | L5: 💎 TOTAL SAVINGS | Q5: ⚖️ NET BALANCE
B7: =G28 -> 72200 | G7: =G31 -> 46944 | L7: =G32 -> 16590 | Q7: =G33 -> 8666
B10: 💵 INCOME | G10: 🏠 FIXED EXPENSES (Bills + EMIs) | L10: 🛍️ VARIABLE EXPENSES | Q10: 💎 SAVINGS & INVESTMENTS
B11: Category | C11: Planned | D11: Actual | E11: Progress | G11: Category | H11: Planned | I11: Actual | J11: Progress | L11: Category | M11: Planned | N11: Actual | O11: Progress | Q11: Category | R11: Planned | S11: Actual | T11: Progress
B12: 💼 Salary / Full-time Job | C12: 65000 | D12: 65000 | E12: =IF(C12=0,IF(D12=0,0,1),D12/C12) -> 1 | G12: 🏠 Rent / Home Loan EMI | H12: 15000 | I12: 14625 | J12: =IF(H12=0,IF(I12=0,0,1),I12/H12) -> 0.975 | L12: 🛒 Groceries | M12: 6000 | N12: 6120 | O12: =IF(M12=0,IF(N12=0,0,1),N12/M12) -> 1.02 | Q12: 🚨 Emergency Fund | R12: 3000 | S12: 2970 | T12: =IF(R12=0,IF(S12=0,0,1),S12/R12) -> 0.99
B13: 🧑‍💻 Freelance / Side Hustle | C13: 6000 | D13: 6000 | E13: =IF(C13=0,IF(D13=0,0,1),D13/C13) -> 1 | G13: 💡 Electricity Bill | H13: 2200 | I13: 2222 | J13: =IF(H13=0,IF(I13=0,0,1),I13/H13) -> 1.01 | L13: 🍽️ Eating Out / Dining | M13: 2500 | N13: 2450 | O13: =IF(M13=0,IF(N13=0,0,1),N13/M13) -> 0.98 | Q13: 📊 Mutual Fund / SIP | R13: 5000 | S13: 5125 | T13: =IF(R13=0,IF(S13=0,0,1),S13/R13) -> 1.025
B14: 🏢 Business Income | C14: 0 | D14: 0 | E14: =IF(C14=0,IF(D14=0,0,1),D14/C14) -> 0 | G14: 🚰 Water Bill | H14: 300 | I14: 297 | J14: =IF(H14=0,IF(I14=0,0,1),I14/H14) -> 0.99 | L14: ⛽ Transport / Fuel | M14: 2000 | N14: 2100 | O14: =IF(M14=0,IF(N14=0,0,1),N14/M14) -> 1.05 | Q14: 🏦 PPF / EPF | R14: 2000 | S14: 2010 | T14: =IF(R14=0,IF(S14=0,0,1),S14/R14) -> 1.005
B15: 🏠 Rental Income | C15: 0 | D15: 0 | E15: =IF(C15=0,IF(D15=0,0,1),D15/C15) -> 0 | G15: 🌐 Internet / WiFi | H15: 800 | I15: 820 | J15: =IF(H15=0,IF(I15=0,0,1),I15/H15) -> 1.025 | L15: 🛍️ Shopping / Clothing | M15: 3000 | N15: 3030 | O15: =IF(M15=0,IF(N15=0,0,1),N15/M15) -> 1.01 | Q15: 🥇 Stocks / Gold | R15: 1000 | S15: 985 | T15: =IF(R15=0,IF(S15=0,0,1),S15/R15) -> 0.985
B16: 📈 Investment Returns | C16: 1200 | D16: 1200 | E16: =IF(C16=0,IF(D16=0,0,1),D16/C16) -> 1 | G16: 📱 Mobile Recharge | H16: 400 | I16: 402 | J16: =IF(H16=0,IF(I16=0,0,1),I16/H16) -> 1.005 | L16: 🎮 Entertainment | M16: 1000 | N16: 970 | O16: =IF(M16=0,IF(N16=0,0,1),N16/M16) -> 0.97 | Q16: 🔒 Fixed Deposit / RD | R16: 2000 | S16: 2040 | T16: =IF(R16=0,IF(S16=0,0,1),S16/R16) -> 1.02
B17: 🎁 Bonus / Incentive | C17: 0 | D17: 0 | E17: =IF(C17=0,IF(D17=0,0,1),D17/C17) -> 0 | G17: 🛡️ Insurance Premium | H17: 1200 | I17: 1182 | J17: =IF(H17=0,IF(I17=0,0,1),I17/H17) -> 0.985 | L17: 💇 Personal Care | M17: 800 | N17: 832 | O17: =IF(M17=0,IF(N17=0,0,1),N17/M17) -> 1.04 | Q17: 👴 Retirement (NPS) | R17: 1500 | S17: 1500 | T17: =IF(R17=0,IF(S17=0,0,1),S17/R17) -> 1
B18: ➕ Other Income 1 | C18: 0 | D18: 0 | E18: =IF(C18=0,IF(D18=0,0,1),D18/C18) -> 0 | G18: 🚗 Car / Vehicle EMI | H18: 6000 | I18: 6120 | J18: =IF(H18=0,IF(I18=0,0,1),I18/H18) -> 1.02 | L18: 🏥 Health / Medical | M18: 1000 | N18: 1000 | O18: =IF(M18=0,IF(N18=0,0,1),N18/M18) -> 1 | Q18: 🎯 Goal-based Savings | R18: 2000 | S18: 1960 | T18: =IF(R18=0,IF(S18=0,0,1),S18/R18) -> 0.98
B19: ➕ Other Income 2 | C19: 0 | D19: 0 | E19: =IF(C19=0,IF(D19=0,0,1),D19/C19) -> 0 | G19: 🎬 OTT Subscriptions | H19: 500 | I19: 500 | J19: =IF(H19=0,IF(I19=0,0,1),I19/H19) -> 1 | L19: 📚 Education / Courses | M19: 0 | N19: 0 | O19: =IF(M19=0,IF(N19=0,0,1),N19/M19) -> 0 | Q19: ➕ Other Savings | R19: 0 | S19: 0 | T19: =IF(R19=0,IF(S19=0,0,1),S19/R19) -> 0
B20: TOTAL | C20: =SUM(C12:C19) -> 72200 | D20: =SUM(D12:D19) -> 72200 | E20: =IF(C20=0,IF(D20=0,0,1),D20/C20) -> 1 | G20: 🏢 Society / Maintenance | H20: 1500 | I20: 1470 | J20: =IF(H20=0,IF(I20=0,0,1),I20/H20) -> 0.98 | L20: ✈️ Travel / Vacation | M20: 1500 | N20: 1545 | O20: =IF(M20=0,IF(N20=0,0,1),N20/M20) -> 1.03 | Q20: TOTAL | R20: =SUM(R12:R19) -> 16500 | S20: =SUM(S12:S19) -> 16590 | T20: =IF(R20=0,IF(S20=0,0,1),S20/R20) -> 1.0054545
G21: ➕ Other Fixed Expense | H21: 0 | I21: 0 | J21: =IF(H21=0,IF(I21=0,0,1),I21/H21) -> 0 | L21: 🎀 Gifts & Donations | M21: 600 | N21: 594 | O21: =IF(M21=0,IF(N21=0,0,1),N21/M21) -> 0.99
G22: TOTAL | H22: =SUM(H12:H21) -> 27900 | I22: =SUM(I12:I21) -> 27638 | J22: =IF(H22=0,IF(I22=0,0,1),I22/H22) -> 0.99060932 | L22: 🧺 Household Items | M22: 700 | N22: 665 | O22: =IF(M22=0,IF(N22=0,0,1),N22/M22) -> 0.95
L23: ➕ Other Variable Expense | M23: 0 | N23: 0 | O23: =IF(M23=0,IF(N23=0,0,1),N23/M23) -> 0
L24: TOTAL | M24: =SUM(M12:M23) -> 19100 | N24: =SUM(N12:N23) -> 19306 | O24: =IF(M24=0,IF(N24=0,0,1),N24/M24) -> 1.0107853
B26: 📊 MONTHLY SUMMARY
B27: Metric | F27: Planned | G27: Actual | H27: Status
B28: 💵 Total Income | F28: =C20 -> 72200 | G28: =D20 -> 72200 | H28: =IF(G28>=F28,"✅ Goal Met","⚠️ Below Target") -> ✅ Goal Met
B29: 🏠 Total Fixed Expenses | F29: =H22 -> 27900 | G29: =I22 -> 27638 | H29: =IF(G29>F29,"⚠️ Over Budget","✅ On Budget") -> ✅ On Budget
B30: 🛍️ Total Variable Expenses | F30: =M24 -> 19100 | G30: =N24 -> 19306 | H30: =IF(G30>F30,"⚠️ Over Budget","✅ On Budget") -> ⚠️ Over Budget
B31: 🧾 Total Expenses (Fixed + Variable) | F31: =F29+F30 -> 47000 | G31: =G29+G30 -> 46944 | H31: =IF(G31>F31,"⚠️ Over Budget","✅ On Budget") -> ✅ On Budget
B32: 💎 Total Savings & Investments | F32: =R20 -> 16500 | G32: =S20 -> 16590 | H32: =IF(G32>=F32,"✅ Goal Met","⚠️ Below Goal") -> ✅ Goal Met
B33: ⚖️ Remaining Balance | F33: =F28-F31-F32 -> 8700 | G33: =G28-G31-G32 -> 8666 | H33: =IF(G33>=0,"✅ Surplus","⚠️ Deficit") -> ✅ Surplus
B34: 📈 Savings Rate (Savings ÷ Income) | F34: =IF(F28=0,0,F32/F28) -> 0.22853186 | G34: =IF(G28=0,0,G32/G28) -> 0.22977839 | H34: =IF(G34>=0.2,"🌟 Excellent","👍 Keep Going") -> 🌟 Excellent
B36: 💰 REMAINING BALANCE This Month | G36: =G33 -> 8666 | O36: =IF(G33>=0,"✅ You're on track!","⚠️ You've overspent") -> ✅ You're on track!
B41: 💡 Tip: Blue numbers are editable inputs. Black text & percentages auto-calculate — nothing else needs to be touched.
B42: ✨ Premium Budget Tracker 2026 ✨

Sheet Apr
B1: 🏠 DASHBOARD | F1: ✨ PREMIUM MONTHLY BUDGET TRACKER ✨ | N1: ◀ Mar | R1: May ▶
B2: 🌧️ APRIL
B3: Monthly Budget Tracker • Edit only the blue input cells
B5: 💵 TOTAL INCOME | G5: 🧾 TOTAL EXPENSES | L5: 💎 TOTAL SAVINGS | Q5: ⚖️ NET BALANCE
B7: =G28 -> 74200 | G7: =G31 -> 47821 | L7: =G32 -> 17325 | Q7: =G33 -> 9054
B10: 💵 INCOME | G10: 🏠 FIXED EXPENSES (Bills + EMIs) | L10: 🛍️ VARIABLE EXPENSES | Q10: 💎 SAVINGS & INVESTMENTS
B11: Category | C11: Planned | D11: Actual | E11: Progress | G11: Category | H11: Planned | I11: Actual | J11: Progress | L11: Category | M11: Planned | N11: Actual | O11: Progress | Q11: Category | R11: Planned | S11: Actual | T11: Progress
B12: 💼 Salary / Full-time Job | C12: 67000 | D12: 67000 | E12: =IF(C12=0,IF(D12=0,0,1),D12/C12) -> 1 | G12: 🏠 Rent / Home Loan EMI | H12: 15000 | I12: 14775 | J12: =IF(H12=0,IF(I12=0,0,1),I12/H12) -> 0.985 | L12: 🛒 Groceries | M12: 6000 | N12: 6240 | O12: =IF(M12=0,IF(N12=0,0,1),N12/M12) -> 1.04 | Q12: 🚨 Emergency Fund | R12: 3000 | S12: 3150 | T12: =IF(R12=0,IF(S12=0,0,1),S12/R12) -> 1.05
B13: 🧑‍💻 Freelance / Side Hustle | C13: 6000 | D13: 6000 | E13: =IF(C13=0,IF(D13=0,0,1),D13/C13) -> 1 | G13: 💡 Electricity Bill | H13: 3080 | I13: 3142 | J13: =IF(H13=0,IF(I13=0,0,1),I13/H13) -> 1.0201299 | L13: 🍽️ Eating Out / Dining | M13: 2500 | N13: 2500 | O13: =IF(M13=0,IF(N13=0,0,1),N13/M13) -> 1 | Q13: 📊 Mutual Fund / SIP | R13: 5000 | S13: 5250 | T13: =IF(R13=0,IF(S13=0,0,1),S13/R13) -> 1.05
B14: 🏢 Business Income | C14: 0 | D14: 0 | E14: =IF(C14=0,IF(D14=0,0,1),D14/C14) -> 0 | G14: 🚰 Water Bill | H14: 300 | I14: 300 | J14: =IF(H14=0,IF(I14=0,0,1),I14/H14) -> 1 | L14: ⛽ Transport / Fuel | M14: 2000 | N14: 1920 | O14: =IF(M14=0,IF(N14=0,0,1),N14/M14) -> 0.96 | Q14: 🏦 PPF / EPF | R14: 2000 | S14: 2100 | T14: =IF(R14=0,IF(S14=0,0,1),S14/R14) -> 1.05
B15: 🏠 Rental Income | C15: 0 | D15: 0 | E15: =IF(C15=0,IF(D15=0,0,1),D15/C15) -> 0 | G15: 🌐 Internet / WiFi | H15: 800 | I15: 784 | J15: =IF(H15=0,IF(I15=0,0,1),I15/H15) -> 0.98 | L15: 🛍️ Shopping / Clothing | M15: 3000 | N15: 3090 | O15: =IF(M15=0,IF(N15=0,0,1),N15/M15) -> 1.03 | Q15: 🥇 Stocks / Gold | R15: 1000 | S15: 1050 | T15: =IF(R15=0,IF(S15=0,0,1),S15/R15) -> 1.05
B16: 📈 Investment Returns | C16: 1200 | D16: 1200 | E16: =IF(C16=0,IF(D16=0,0,1),D16/C16) -> 1 | G16: 📱 Mobile Recharge | H16: 400 | I16: 406 | J16: =IF(H16=0,IF(I16=0,0,1),I16/H16) -> 1.015 | L16: 🎮 Entertainment | M16: 1000 | N16: 990 | O16: =IF(M16=0,IF(N16=0,0,1),N16/M16) -> 0.99 | Q16: 🔒 Fixed Deposit / RD | R16: 2000 | S16: 2100 | T16: =IF(R16=0,IF(S16=0,0,1),S16/R16) -> 1.05
B17: 🎁 Bonus / Incentive | C17: 0 | D17: 0 | E17: =IF(C17=0,IF(D17=0,0,1),D17/C17) -> 0 | G17: 🛡️ Insurance Premium | H17: 1200 | I17: 1194 | J17: =IF(H17=0,IF(I17=0,0,1),I17/H17) -> 0.995 | L17: 💇 Personal Care | M17: 800 | N17: 760 | O17: =IF(M17=0,IF(N17=0,0,1),N17/M17) -> 0.95 | Q17: 👴 Retirement (NPS) | R17: 1500 | S17: 1575 | T17: =IF(R17=0,IF(S17=0,0,1),S17/R17) -> 1.05
B18: ➕ Other Income 1 | C18: 0 | D18: 0 | E18: =IF(C18=0,IF(D18=0,0,1),D18/C18) -> 0 | G18: 🚗 Car / Vehicle EMI | H18: 6000 | I18: 5850 | J18: =IF(H18=0,IF(I18=0,0,1),I18/H18) -> 0.975 | L18: 🏥 Health / Medical | M18: 1000 | N18: 1020 | O18: =IF(M18=0,IF(N18=0,0,1),N18/M18) -> 1.02 | Q18: 🎯 Goal-based Savings | R18: 2000 | S18: 2100 | T18: =IF(R18=0,IF(S18=0,0,1),S18/R18) -> 1.05
B19: ➕ Other Income 2 | C19: 0 | D19: 0 | E19: =IF(C19=0,IF(D19=0,0,1),D19/C19) -> 0 | G19: 🎬 OTT Subscriptions | H19: 500 | I19: 505 | J19: =IF(H19=0,IF(I19=0,0,1),I19/H19) -> 1.01 | L19: 📚 Education / Courses | M19: 0 | N19: 0 | O19: =IF(M19=0,IF(N19=0,0,1),N19/M19) -> 0 | Q19: ➕ Other Savings | R19: 0 | S19: 0 | T19: =IF(R19=0,IF(S19=0,0,1),S19/R19) -> 0
B20: TOTAL | C20: =SUM(C12:C19) -> 74200 | D20: =SUM(D12:D19) -> 74200 | E20: =IF(C20=0,IF(D20=0,0,1),D20/C20) -> 1 | G20: 🏢 Society / Maintenance | H20: 1500 | I20: 1485 | J20: =IF(H20=0,IF(I20=0,0,1),I20/H20) -> 0.99 | L20: ✈️ Travel / Vacation | M20: 1500 | N20: 1575 | O20: =IF(M20=0,IF(N20=0,0,1),N20/M20) -> 1.05 | Q20: TOTAL | R20: =SUM(R12:R19) -> 16500 | S20: =SUM(S12:S19) -> 17325 | T20: =IF(R20=0,IF(S20=0,0,1),S20/R20) -> 1.05
G21: ➕ Other Fixed Expense | H21: 0 | I21: 0 | J21: =IF(H21=0,IF(I21=0,0,1),I21/H21) -> 0 | L21: 🎀 Gifts & Donations | M21: 600 | N21: 606 | O21: =IF(M21=0,IF(N21=0,0,1),N21/M21) -> 1.01
G22: TOTAL | H22: =SUM(H12:H21) -> 28780 | I22: =SUM(I12:I21) -> 28441 | J22: =IF(H22=0,IF(I22=0,0,1),I22/H22) -> 0.98822099 | L22: 🧺 Household Items | M22: 700 | N22: 679 | O22: =IF(M22=0,IF(N22=0,0,1),N22/M22) -> 0.97
L23: ➕ Other Variable Expense | M23: 0 | N23: 0 | O23: =IF(M23=0,IF(N23=0,0,1),N23/M23) -> 0
L24: TOTAL | M24: =SUM(M12:M23) -> 19100 | N24: =SUM(N12:N23) -> 19380 | O24: =IF(M24=0,IF(N24=0,0,1),N24/M24) -> 1.0146597
B26: 📊 MONTHLY SUMMARY
B27: Metric | F27: Planned | G27: Actual | H27: Status
B28: 💵 Total Income | F28: =C20 -> 74200 | G28: =D20 -> 74200 | H28: =IF(G28>=F28,"✅ Goal Met","⚠️ Below Target") -> ✅ Goal Met
B29: 🏠 Total Fixed Expenses | F29: =H22 -> 28780 | G29: =I22 -> 28441 | H29: =IF(G29>F29,"⚠️ Over Budget","✅ On Budget") -> ✅ On Budget
B30: 🛍️ Total Variable Expenses | F30: =M24 -> 19100 | G30: =N24 -> 19380 | H30: =IF(G30>F30,"⚠️ Over Budget","✅ On Budget") -> ⚠️ Over Budget
B31: 🧾 Total Expenses (Fixed + Variable) | F31: =F29+F30 -> 47880 | G31: =G29+G30 -> 47821 | H31: =IF(G31>F31,"⚠️ Over Budget","✅ On Budget") -> ✅ On Budget
B32: 💎 Total Savings & Investments | F32: =R20 -> 16500 | G32: =S20 -> 17325 | H32: =IF(G32>=F32,"✅ Goal Met","⚠️ Below Goal") -> ✅ Goal Met
B33: ⚖️ Remaining Balance | F33: =F28-F31-F32 -> 9820 | G33: =G28-G31-G32 -> 9054 | H33: =IF(G33>=0,"✅ Surplus","⚠️ Deficit") -> ✅ Surplus
B34: 📈 Savings Rate (Savings ÷ Income) | F34: =IF(F28=0,0,F32/F28) -> 0.22237197 | G34: =IF(G28=0,0,G32/G28) -> 0.23349057 | H34: =IF(G34>=0.2,"🌟 Excellent","👍 Keep Going") -> 🌟 Excellent
B36: 💰 REMAINING BALANCE This Month | G36: =G33 -> 9054 | O36: =IF(G33>=0,"✅ You're on track!","⚠️ You've overspent") -> ✅ You're on track!
B41: 💡 Tip: Blue numbers are editable inputs. Black text & percentages auto-calculate — nothing else needs to be touched.
B42: ✨ Premium Budget Tracker 2026 ✨

Sheet May
B1: 🏠 DASHBOARD | F1: ✨ PREMIUM MONTHLY BUDGET TRACKER ✨ | N1: ◀ Apr | R1: Jun ▶
B2: 🌸 MAY
B3: Monthly Budget Tracker • Edit only the blue input cells
B5: 💵 TOTAL INCOME | G5: 🧾 TOTAL EXPENSES | L5: 💎 TOTAL SAVINGS | Q5: ⚖️ NET BALANCE
B7: =G28 -> 74200 | G7: =G31 -> 55125 | L7: =G32 -> 16535 | Q7: =G33 -> 2540
B10: 💵 INCOME | G10: 🏠 FIXED EXPENSES (Bills + EMIs) | L10: 🛍️ VARIABLE EXPENSES | Q10: 💎 SAVINGS & INVESTMENTS
B11: Category | C11: Planned | D11: Actual | E11: Progress | G11: Category | H11: Planned | I11: Actual | J11: Progress | L11: Category | M11: Planned | N11: Actual | O11: Progress | Q11: Category | R11: Planned | S11: Actual | T11: Progress
B12: 💼 Salary / Full-time Job | C12: 67000 | D12: 67000 | E12: =IF(C12=0,IF(D12=0,0,1),D12/C12) -> 1 | G12: 🏠 Rent / Home Loan EMI | H12: 15000 | I12: 14925 | J12: =IF(H12=0,IF(I12=0,0,1),I12/H12) -> 0.995 | L12: 🛒 Groceries | M12: 6000 | N12: 5700 | O12: =IF(M12=0,IF(N12=0,0,1),N12/M12) -> 0.95 | Q12: 🚨 Emergency Fund | R12: 3000 | S12: 3030 | T12: =IF(R12=0,IF(S12=0,0,1),S12/R12) -> 1.01
B13: 🧑‍💻 Freelance / Side Hustle | C13: 6000 | D13: 6000 | E13: =IF(C13=0,IF(D13=0,0,1),D13/C13) -> 1 | G13: 💡 Electricity Bill | H13: 3520 | I13: 3432 | J13: =IF(H13=0,IF(I13=0,0,1),I13/H13) -> 0.975 | L13: 🍽️ Eating Out / Dining | M13: 2500 | N13: 2550 | O13: =IF(M13=0,IF(N13=0,0,1),N13/M13) -> 1.02 | Q13: 📊 Mutual Fund / SIP | R13: 5000 | S13: 4950 | T13: =IF(R13=0,IF(S13=0,0,1),S13/R13) -> 0.99
B14: 🏢 Business Income | C14: 0 | D14: 0 | E14: =IF(C14=0,IF(D14=0,0,1),D14/C14) -> 0 | G14: 🚰 Water Bill | H14: 300 | I14: 303 | J14: =IF(H14=0,IF(I14=0,0,1),I14/H14) -> 1.01 | L14: ⛽ Transport / Fuel | M14: 2000 | N14: 1960 | O14: =IF(M14=0,IF(N14=0,0,1),N14/M14) -> 0.98 | Q14: 🏦 PPF / EPF | R14: 2000 | S14: 2050 | T14: =IF(R14=0,IF(S14=0,0,1),S14/R14) -> 1.025
B15: 🏠 Rental Income | C15: 0 | D15: 0 | E15: =IF(C15=0,IF(D15=0,0,1),D15/C15) -> 0 | G15: 🌐 Internet / WiFi | H15: 800 | I15: 792 | J15: =IF(H15=0,IF(I15=0,0,1),I15/H15) -> 0.99 | L15: 🛍️ Shopping / Clothing | M15: 3000 | N15: 3150 | O15: =IF(M15=0,IF(N15=0,0,1),N15/M15) -> 1.05 | Q15: 🥇 Stocks / Gold | R15: 1000 | S15: 1005 | T15: =IF(R15=0,IF(S15=0,0,1),S15/R15) -> 1.005
B16: 📈 Investment Returns | C16: 1200 | D16: 1200 | E16: =IF(C16=0,IF(D16=0,0,1),D16/C16) -> 1 | G16: 📱 Mobile Recharge | H16: 400 | I16: 410 | J16: =IF(H16=0,IF(I16=0,0,1),I16/H16) -> 1.025 | L16: 🎮 Entertainment | M16: 1000 | N16: 1010 | O16: =IF(M16=0,IF(N16=0,0,1),N16/M16) -> 1.01 | Q16: 🔒 Fixed Deposit / RD | R16: 2000 | S16: 1970 | T16: =IF(R16=0,IF(S16=0,0,1),S16/R16) -> 0.985
B17: 🎁 Bonus / Incentive | C17: 0 | D17: 0 | E17: =IF(C17=0,IF(D17=0,0,1),D17/C17) -> 0 | G17: 🛡️ Insurance Premium | H17: 1200 | I17: 1206 | J17: =IF(H17=0,IF(I17=0,0,1),I17/H17) -> 1.005 | L17: 💇 Personal Care | M17: 800 | N17: 776 | O17: =IF(M17=0,IF(N17=0,0,1),N17/M17) -> 0.97 | Q17: 👴 Retirement (NPS) | R17: 1500 | S17: 1530 | T17: =IF(R17=0,IF(S17=0,0,1),S17/R17) -> 1.02
B18: ➕ Other Income 1 | C18: 0 | D18: 0 | E18: =IF(C18=0,IF(D18=0,0,1),D18/C18) -> 0 | G18: 🚗 Car / Vehicle EMI | H18: 6000 | I18: 5910 | J18: =IF(H18=0,IF(I18=0,0,1),I18/H18) -> 0.985 | L18: 🏥 Health / Medical | M18: 1000 | N18: 1040 | O18: =IF(M18=0,IF(N18=0,0,1),N18/M18) -> 1.04 | Q18: 🎯 Goal-based Savings | R18: 2000 | S18: 2000 | T18: =IF(R18=0,IF(S18=0,0,1),S18/R18) -> 1
B19: ➕ Other Income 2 | C19: 0 | D19: 0 | E19: =IF(C19=0,IF(D19=0,0,1),D19/C19) -> 0 | G19: 🎬 OTT Subscriptions | H19: 500 | I19: 510 | J19: =IF(H19=0,IF(I19=0,0,1),I19/H19) -> 1.02 | L19: 📚 Education / Courses | M19: 0 | N19: 0 | O19: =IF(M19=0,IF(N19=0,0,1),N19/M19) -> 0 | Q19: ➕ Other Savings | R19: 0 | S19: 0 | T19: =IF(R19=0,IF(S19=0,0,1),S19/R19) -> 0
B20: TOTAL | C20: =SUM(C12:C19) -> 74200 | D20: =SUM(D12:D19) -> 74200 | E20: =IF(C20=0,IF(D20=0,0,1),D20/C20) -> 1 | G20: 🏢 Society / Maintenance | H20: 1500 | I20: 1500 | J20: =IF(H20=0,IF(I20=0,0,1),I20/H20) -> 1 | L20: ✈️ Travel / Vacation | M20: 9000 | N20: 8640 | O20: =IF(M20=0,IF(N20=0,0,1),N20/M20) -> 0.96 | Q20: TOTAL | R20: =SUM(R12:R19) -> 16500 | S20: =SUM(S12:S19) -> 16535 | T20: =IF(R20=0,IF(S20=0,0,1),S20/R20) -> 1.0021212
G21: ➕ Other Fixed Expense | H21: 0 | I21: 0 | J21: =IF(H21=0,IF(I21=0,0,1),I21/H21) -> 0 | L21: 🎀 Gifts & Donations | M21: 600 | N21: 618 | O21: =IF(M21=0,IF(N21=0,0,1),N21/M21) -> 1.03
G22: TOTAL | H22: =SUM(H12:H21) -> 29220 | I22: =SUM(I12:I21) -> 28988 | J22: =IF(H22=0,IF(I22=0,0,1),I22/H22) -> 0.99206023 | L22: 🧺 Household Items | M22: 700 | N22: 693 | O22: =IF(M22=0,IF(N22=0,0,1),N22/M22) -> 0.99
L23: ➕ Other Variable Expense | M23: 0 | N23: 0 | O23: =IF(M23=0,IF(N23=0,0,1),N23/M23) -> 0
L24: TOTAL | M24: =SUM(M12:M23) -> 26600 | N24: =SUM(N12:N23) -> 26137 | O24: =IF(M24=0,IF(N24=0,0,1),N24/M24) -> 0.98259398
B26: 📊 MONTHLY SUMMARY
B27: Metric | F27: Planned | G27: Actual | H27: Status
B28: 💵 Total Income | F28: =C20 -> 74200 | G28: =D20 -> 74200 | H28: =IF(G28>=F28,"✅ Goal Met","⚠️ Below Target") -> ✅ Goal Met
B29: 🏠 Total Fixed Expenses | F29: =H22 -> 29220 | G29: =I22 -> 28988 | H29: =IF(G29>F29,"⚠️ Over Budget","✅ On Budget") -> ✅ On Budget
B30: 🛍️ Total Variable Expenses | F30: =M24 -> 26600 | G30: =N24 -> 26137 | H30: =IF(G30>F30,"⚠️ Over Budget","✅ On Budget") -> ✅ On Budget
B31: 🧾 Total Expenses (Fixed + Variable) | F31: =F29+F30 -> 55820 | G31: =G29+G30 -> 55125 | H31: =IF(G31>F31,"⚠️ Over Budget","✅ On Budget") -> ✅ On Budget
B32: 💎 Total Savings & Investments | F32: =R20 -> 16500 | G32: =S20 -> 16535 | H32: =IF(G32>=F32,"✅ Goal Met","⚠️ Below Goal") -> ✅ Goal Met
B33: ⚖️ Remaining Balance | F33: =F28-F31-F32 -> 1880 | G33: =G28-G31-G32 -> 2540 | H33: =IF(G33>=0,"✅ Surplus","⚠️ Deficit") -> ✅ Surplus
B34: 📈 Savings Rate (Savings ÷ Income) | F34: =IF(F28=0,0,F32/F28) -> 0.22237197 | G34: =IF(G28=0,0,G32/G28) -> 0.22284367 | H34: =IF(G34>=0.2,"🌟 Excellent","👍 Keep Going") -> 🌟 Excellent
B36: 💰 REMAINING BALANCE This Month | G36: =G33 -> 2540 | O36: =IF(G33>=0,"✅ You're on track!","⚠️ You've overspent") -> ✅ You're on track!
B41: 💡 Tip: Blue numbers are editable inputs. Black text & percentages auto-calculate — nothing else needs to be touched.
B42: ✨ Premium Budget Tracker 2026 ✨

Sheet Jun
B1: 🏠 DASHBOARD | F1: ✨ PREMIUM MONTHLY BUDGET TRACKER ✨ | N1: ◀ May | R1: Jul ▶
B2: ☀️ JUNE
B3: Monthly Budget Tracker • Edit only the blue input cells
B5: 💵 TOTAL INCOME | G5: 🧾 TOTAL EXPENSES | L5: 💎 TOTAL SAVINGS | Q5: ⚖️ NET BALANCE
B7: =G28 -> 74200 | G7: =G31 -> 47893 | L7: =G32 -> 16507 | Q7: =G33 -> 9800
B10: 💵 INCOME | G10: 🏠 FIXED EXPENSES (Bills + EMIs) | L10: 🛍️ VARIABLE EXPENSES | Q10: 💎 SAVINGS & INVESTMENTS
B11: Category | C11: Planned | D11: Actual | E11: Progress | G11: Category | H11: Planned | I11: Actual | J11: Progress | L11: Category | M11: Planned | N11: Actual | O11: Progress | Q11: Category | R11: Planned | S11: Actual | T11: Progress
B12: 💼 Salary / Full-time Job | C12: 67000 | D12: 67000 | E12: =IF(C12=0,IF(D12=0,0,1),D12/C12) -> 1 | G12: 🏠 Rent / Home Loan EMI | H12: 15000 | I12: 15075 | J12: =IF(H12=0,IF(I12=0,0,1),I12/H12) -> 1.005 | L12: 🛒 Groceries | M12: 6000 | N12: 5820 | O12: =IF(M12=0,IF(N12=0,0,1),N12/M12) -> 0.97 | Q12: 🚨 Emergency Fund | R12: 3000 | S12: 3060 | T12: =IF(R12=0,IF(S12=0,0,1),S12/R12) -> 1.02
B13: 🧑‍💻 Freelance / Side Hustle | C13: 6000 | D13: 6000 | E13: =IF(C13=0,IF(D13=0,0,1),D13/C13) -> 1 | G13: 💡 Electricity Bill | H13: 3300 | I13: 3250 | J13: =IF(H13=0,IF(I13=0,0,1),I13/H13) -> 0.98484848 | L13: 🍽️ Eating Out / Dining | M13: 2500 | N13: 2600 | O13: =IF(M13=0,IF(N13=0,0,1),N13/M13) -> 1.04 | Q13: 📊 Mutual Fund / SIP | R13: 5000 | S13: 5000 | T13: =IF(R13=0,IF(S13=0,0,1),S13/R13) -> 1
B14: 🏢 Business Income | C14: 0 | D14: 0 | E14: =IF(C14=0,IF(D14=0,0,1),D14/C14) -> 0 | G14: 🚰 Water Bill | H14: 300 | I14: 306 | J14: =IF(H14=0,IF(I14=0,0,1),I14/H14) -> 1.02 | L14: ⛽ Transport / Fuel | M14: 2000 | N14: 2000 | O14: =IF(M14=0,IF(N14=0,0,1),N14/M14) -> 1 | Q14: 🏦 PPF / EPF | R14: 2000 | S14: 1960 | T14: =IF(R14=0,IF(S14=0,0,1),S14/R14) -> 0.98
B15: 🏠 Rental Income | C15: 0 | D15: 0 | E15: =IF(C15=0,IF(D15=0,0,1),D15/C15) -> 0 | G15: 🌐 Internet / WiFi | H15: 800 | I15: 800 | J15: =IF(H15=0,IF(I15=0,0,1),I15/H15) -> 1 | L15: 🛍️ Shopping / Clothing | M15: 3000 | N15: 2880 | O15: =IF(M15=0,IF(N15=0,0,1),N15/M15) -> 0.96 | Q15: 🥇 Stocks / Gold | R15: 1000 | S15: 1015 | T15: =IF(R15=0,IF(S15=0,0,1),S15/R15) -> 1.015
B16: 📈 Investment Returns | C16: 1200 | D16: 1200 | E16: =IF(C16=0,IF(D16=0,0,1),D16/C16) -> 1 | G16: 📱 Mobile Recharge | H16: 400 | I16: 392 | J16: =IF(H16=0,IF(I16=0,0,1),I16/H16) -> 0.98 | L16: 🎮 Entertainment | M16: 1000 | N16: 1030 | O16: =IF(M16=0,IF(N16=0,0,1),N16/M16) -> 1.03 | Q16: 🔒 Fixed Deposit / RD | R16: 2000 | S16: 1990 | T16: =IF(R16=0,IF(S16=0,0,1),S16/R16) -> 0.995
B17: 🎁 Bonus / Incentive | C17: 0 | D17: 0 | E17: =IF(C17=0,IF(D17=0,0,1),D17/C17) -> 0 | G17: 🛡️ Insurance Premium | H17: 1200 | I17: 1218 | J17: =IF(H17=0,IF(I17=0,0,1),I17/H17) -> 1.015 | L17: 💇 Personal Care | M17: 800 | N17: 792 | O17: =IF(M17=0,IF(N17=0,0,1),N17/M17) -> 0.99 | Q17: 👴 Retirement (NPS) | R17: 1500 | S17: 1462 | T17: =IF(R17=0,IF(S17=0,0,1),S17/R17) -> 0.97466667
B18: ➕ Other Income 1 | C18: 0 | D18: 0 | E18: =IF(C18=0,IF(D18=0,0,1),D18/C18) -> 0 | G18: 🚗 Car / Vehicle EMI | H18: 6000 | I18: 5970 | J18: =IF(H18=0,IF(I18=0,0,1),I18/H18) -> 0.995 | L18: 🏥 Health / Medical | M18: 1000 | N18: 950 | O18: =IF(M18=0,IF(N18=0,0,1),N18/M18) -> 0.95 | Q18: 🎯 Goal-based Savings | R18: 2000 | S18: 2020 | T18: =IF(R18=0,IF(S18=0,0,1),S18/R18) -> 1.01
B19: ➕ Other Income 2 | C19: 0 | D19: 0 | E19: =IF(C19=0,IF(D19=0,0,1),D19/C19) -> 0 | G19: 🎬 OTT Subscriptions | H19: 500 | I19: 488 | J19: =IF(H19=0,IF(I19=0,0,1),I19/H19) -> 0.976 | L19: 📚 Education / Courses | M19: 0 | N19: 0 | O19: =IF(M19=0,IF(N19=0,0,1),N19/M19) -> 0 | Q19: ➕ Other Savings | R19: 0 | S19: 0 | T19: =IF(R19=0,IF(S19=0,0,1),S19/R19) -> 0
B20: TOTAL | C20: =SUM(C12:C19) -> 74200 | D20: =SUM(D12:D19) -> 74200 | E20: =IF(C20=0,IF(D20=0,0,1),D20/C20) -> 1 | G20: 🏢 Society / Maintenance | H20: 1500 | I20: 1515 | J20: =IF(H20=0,IF(I20=0,0,1),I20/H20) -> 1.01 | L20: ✈️ Travel / Vacation | M20: 1500 | N20: 1470 | O20: =IF(M20=0,IF(N20=0,0,1),N20/M20) -> 0.98 | Q20: TOTAL | R20: =SUM(R12:R19) -> 16500 | S20: =SUM(S12:S19) -> 16507 | T20: =IF(R20=0,IF(S20=0,0,1),S20/R20) -> 1.0004242
G21: ➕ Other Fixed Expense | H21: 0 | I21: 0 | J21: =IF(H21=0,IF(I21=0,0,1),I21/H21) -> 0 | L21: 🎀 Gifts & Donations | M21: 600 | N21: 630 | O21: =IF(M21=0,IF(N21=0,0,1),N21/M21) -> 1.05
G22: TOTAL | H22: =SUM(H12:H21) -> 29000 | I22: =SUM(I12:I21) -> 29014 | J22: =IF(H22=0,IF(I22=0,0,1),I22/H22) -> 1.0004828 | L22: 🧺 Household Items | M22: 700 | N22: 707 | O22: =IF(M22=0,IF(N22=0,0,1),N22/M22) -> 1.01
L23: ➕ Other Variable Expense | M23: 0 | N23: 0 | O23: =IF(M23=0,IF(N23=0,0,1),N23/M23) -> 0
L24: TOTAL | M24: =SUM(M12:M23) -> 19100 | N24: =SUM(N12:N23) -> 18879 | O24: =IF(M24=0,IF(N24=0,0,1),N24/M24) -> 0.98842932
B26: 📊 MONTHLY SUMMARY
B27: Metric | F27: Planned | G27: Actual | H27: Status
B28: 💵 Total Income | F28: =C20 -> 74200 | G28: =D20 -> 74200 | H28: =IF(G28>=F28,"✅ Goal Met","⚠️ Below Target") -> ✅ Goal Met
B29: 🏠 Total Fixed Expenses | F29: =H22 -> 29000 | G29: =I22 -> 29014 | H29: =IF(G29>F29,"⚠️ Over Budget","✅ On Budget") -> ⚠️ Over Budget
B30: 🛍️ Total Variable Expenses | F30: =M24 -> 19100 | G30: =N24 -> 18879 | H30: =IF(G30>F30,"⚠️ Over Budget","✅ On Budget") -> ✅ On Budget
B31: 🧾 Total Expenses (Fixed + Variable) | F31: =F29+F30 -> 48100 | G31: =G29+G30 -> 47893 | H31: =IF(G31>F31,"⚠️ Over Budget","✅ On Budget") -> ✅ On Budget
B32: 💎 Total Savings & Investments | F32: =R20 -> 16500 | G32: =S20 -> 16507 | H32: =IF(G32>=F32,"✅ Goal Met","⚠️ Below Goal") -> ✅ Goal Met
B33: ⚖️ Remaining Balance | F33: =F28-F31-F32 -> 9600 | G33: =G28-G31-G32 -> 9800 | H33: =IF(G33>=0,"✅ Surplus","⚠️ Deficit") -> ✅ Surplus
B34: 📈 Savings Rate (Savings ÷ Income) | F34: =IF(F28=0,0,F32/F28) -> 0.22237197 | G34: =IF(G28=0,0,G32/G28) -> 0.22246631 | H34: =IF(G34>=0.2,"🌟 Excellent","👍 Keep Going") -> 🌟 Excellent
B36: 💰 REMAINING BALANCE This Month | G36: =G33 -> 9800 | O36: =IF(G33>=0,"✅ You're on track!","⚠️ You've overspent") -> ✅ You're on track!
B41: 💡 Tip: Blue numbers are editable inputs. Black text & percentages auto-calculate — nothing else needs to be touched.
B42: ✨ Premium Budget Tracker 2026 ✨

Sheet Jul
B1: 🏠 DASHBOARD | F1: ✨ PREMIUM MONTHLY BUDGET TRACKER ✨ | N1: ◀ Jun | R1: Aug ▶
B2: 🌧️ JULY
B3: Monthly Budget Tracker • Edit only the blue input cells
B5: 💵 TOTAL INCOME | G5: 🧾 TOTAL EXPENSES | L5: 💎 TOTAL SAVINGS | Q5: ⚖️ NET BALANCE
B7: =G28 -> 86200 | G7: =G31 -> 47550 | L7: =G32 -> 18150 | Q7: =G33 -> 20500
B10: 💵 INCOME | G10: 🏠 FIXED EXPENSES (Bills + EMIs) | L10: 🛍️ VARIABLE EXPENSES | Q10: 💎 SAVINGS & INVESTMENTS
B11: Category | C11: Planned | D11: Actual | E11: Progress | G11: Category | H11: Planned | I11: Actual | J11: Progress | L11: Category | M11: Planned | N11: Actual | O11: Progress | Q11: Category | R11: Planned | S11: Actual | T11: Progress
B12: 💼 Salary / Full-time Job | C12: 69000 | D12: 69000 | E12: =IF(C12=0,IF(D12=0,0,1),D12/C12) -> 1 | G12: 🏠 Rent / Home Loan EMI | H12: 15000 | I12: 15225 | J12: =IF(H12=0,IF(I12=0,0,1),I12/H12) -> 1.015 | L12: 🛒 Groceries | M12: 6000 | N12: 5940 | O12: =IF(M12=0,IF(N12=0,0,1),N12/M12) -> 0.99 | Q12: 🚨 Emergency Fund | R12: 3000 | S12: 3300 | T12: =IF(R12=0,IF(S12=0,0,1),S12/R12) -> 1.1
B13: 🧑‍💻 Freelance / Side Hustle | C13: 6000 | D13: 6000 | E13: =IF(C13=0,IF(D13=0,0,1),D13/C13) -> 1 | G13: 💡 Electricity Bill | H13: 2640 | I13: 2627 | J13: =IF(H13=0,IF(I13=0,0,1),I13/H13) -> 0.99507576 | L13: 🍽️ Eating Out / Dining | M13: 2500 | N13: 2375 | O13: =IF(M13=0,IF(N13=0,0,1),N13/M13) -> 0.95 | Q13: 📊 Mutual Fund / SIP | R13: 5000 | S13: 5500 | T13: =IF(R13=0,IF(S13=0,0,1),S13/R13) -> 1.1
B14: 🏢 Business Income | C14: 0 | D14: 0 | E14: =IF(C14=0,IF(D14=0,0,1),D14/C14) -> 0 | G14: 🚰 Water Bill | H14: 300 | I14: 292 | J14: =IF(H14=0,IF(I14=0,0,1),I14/H14) -> 0.97333333 | L14: ⛽ Transport / Fuel | M14: 2000 | N14: 2040 | O14: =IF(M14=0,IF(N14=0,0,1),N14/M14) -> 1.02 | Q14: 🏦 PPF / EPF | R14: 2000 | S14: 2200 | T14: =IF(R14=0,IF(S14=0,0,1),S14/R14) -> 1.1
B15: 🏠 Rental Income | C15: 0 | D15: 0 | E15: =IF(C15=0,IF(D15=0,0,1),D15/C15) -> 0 | G15: 🌐 Internet / WiFi | H15: 800 | I15: 808 | J15: =IF(H15=0,IF(I15=0,0,1),I15/H15) -> 1.01 | L15: 🛍️ Shopping / Clothing | M15: 3000 | N15: 2940 | O15: =IF(M15=0,IF(N15=0,0,1),N15/M15) -> 0.98 | Q15: 🥇 Stocks / Gold | R15: 1000 | S15: 1100 | T15: =IF(R15=0,IF(S15=0,0,1),S15/R15) -> 1.1
B16: 📈 Investment Returns | C16: 1200 | D16: 1200 | E16: =IF(C16=0,IF(D16=0,0,1),D16/C16) -> 1 | G16: 📱 Mobile Recharge | H16: 400 | I16: 396 | J16: =IF(H16=0,IF(I16=0,0,1),I16/H16) -> 0.99 | L16: 🎮 Entertainment | M16: 1000 | N16: 1050 | O16: =IF(M16=0,IF(N16=0,0,1),N16/M16) -> 1.05 | Q16: 🔒 Fixed Deposit / RD | R16: 2000 | S16: 2200 | T16: =IF(R16=0,IF(S16=0,0,1),S16/R16) -> 1.1
B17: 🎁 Bonus / Incentive | C17: 10000 | D17: 10000 | E17: =IF(C17=0,IF(D17=0,0,1),D17/C17) -> 1 | G17: 🛡️ Insurance Premium | H17: 1200 | I17: 1230 | J17: =IF(H17=0,IF(I17=0,0,1),I17/H17) -> 1.025 | L17: 💇 Personal Care | M17: 800 | N17: 808 | O17: =IF(M17=0,IF(N17=0,0,1),N17/M17) -> 1.01 | Q17: 👴 Retirement (NPS) | R17: 1500 | S17: 1650 | T17: =IF(R17=0,IF(S17=0,0,1),S17/R17) -> 1.1
B18: ➕ Other Income 1 | C18: 0 | D18: 0 | E18: =IF(C18=0,IF(D18=0,0,1),D18/C18) -> 0 | G18: 🚗 Car / Vehicle EMI | H18: 6000 | I18: 6030 | J18: =IF(H18=0,IF(I18=0,0,1),I18/H18) -> 1.005 | L18: 🏥 Health / Medical | M18: 1000 | N18: 970 | O18: =IF(M18=0,IF(N18=0,0,1),N18/M18) -> 0.97 | Q18: 🎯 Goal-based Savings | R18: 2000 | S18: 2200 | T18: =IF(R18=0,IF(S18=0,0,1),S18/R18) -> 1.1
B19: ➕ Other Income 2 | C19: 0 | D19: 0 | E19: =IF(C19=0,IF(D19=0,0,1),D19/C19) -> 0 | G19: 🎬 OTT Subscriptions | H19: 500 | I19: 492 | J19: =IF(H19=0,IF(I19=0,0,1),I19/H19) -> 0.984 | L19: 📚 Education / Courses | M19: 0 | N19: 0 | O19: =IF(M19=0,IF(N19=0,0,1),N19/M19) -> 0 | Q19: ➕ Other Savings | R19: 0 | S19: 0 | T19: =IF(R19=0,IF(S19=0,0,1),S19/R19) -> 0
B20: TOTAL | C20: =SUM(C12:C19) -> 86200 | D20: =SUM(D12:D19) -> 86200 | E20: =IF(C20=0,IF(D20=0,0,1),D20/C20) -> 1 | G20: 🏢 Society / Maintenance | H20: 1500 | I20: 1530 | J20: =IF(H20=0,IF(I20=0,0,1),I20/H20) -> 1.02 | L20: ✈️ Travel / Vacation | M20: 1500 | N20: 1500 | O20: =IF(M20=0,IF(N20=0,0,1),N20/M20) -> 1 | Q20: TOTAL | R20: =SUM(R12:R19) -> 16500 | S20: =SUM(S12:S19) -> 18150 | T20: =IF(R20=0,IF(S20=0,0,1),S20/R20) -> 1.1
G21: ➕ Other Fixed Expense | H21: 0 | I21: 0 | J21: =IF(H21=0,IF(I21=0,0,1),I21/H21) -> 0 | L21: 🎀 Gifts & Donations | M21: 600 | N21: 576 | O21: =IF(M21=0,IF(N21=0,0,1),N21/M21) -> 0.96
G22: TOTAL | H22: =SUM(H12:H21) -> 28340 | I22: =SUM(I12:I21) -> 28630 | J22: =IF(H22=0,IF(I22=0,0,1),I22/H22) -> 1.0102329 | L22: 🧺 Household Items | M22: 700 | N22: 721 | O22: =IF(M22=0,IF(N22=0,0,1),N22/M22) -> 1.03
L23: ➕ Other Variable Expense | M23: 0 | N23: 0 | O23: =IF(M23=0,IF(N23=0,0,1),N23/M23) -> 0
L24: TOTAL | M24: =SUM(M12:M23) -> 19100 | N24: =SUM(N12:N23) -> 18920 | O24: =IF(M24=0,IF(N24=0,0,1),N24/M24) -> 0.99057592
B26: 📊 MONTHLY SUMMARY
B27: Metric | F27: Planned | G27: Actual | H27: Status
B28: 💵 Total Income | F28: =C20 -> 86200 | G28: =D20 -> 86200 | H28: =IF(G28>=F28,"✅ Goal Met","⚠️ Below Target") -> ✅ Goal Met
B29: 🏠 Total Fixed Expenses | F29: =H22 -> 28340 | G29: =I22 -> 28630 | H29: =IF(G29>F29,"⚠️ Over Budget","✅ On Budget") -> ⚠️ Over Budget
B30: 🛍️ Total Variable Expenses | F30: =M24 -> 19100 | G30: =N24 -> 18920 | H30: =IF(G30>F30,"⚠️ Over Budget","✅ On Budget") -> ✅ On Budget
B31: 🧾 Total Expenses (Fixed + Variable) | F31: =F29+F30 -> 47440 | G31: =G29+G30 -> 47550 | H31: =IF(G31>F31,"⚠️ Over Budget","✅ On Budget") -> ⚠️ Over Budget
B32: 💎 Total Savings & Investments | F32: =R20 -> 16500 | G32: =S20 -> 18150 | H32: =IF(G32>=F32,"✅ Goal Met","⚠️ Below Goal") -> ✅ Goal Met
B33: ⚖️ Remaining Balance | F33: =F28-F31-F32 -> 22260 | G33: =G28-G31-G32 -> 20500 | H33: =IF(G33>=0,"✅ Surplus","⚠️ Deficit") -> ✅ Surplus
B34: 📈 Savings Rate (Savings ÷ Income) | F34: =IF(F28=0,0,F32/F28) -> 0.19141531 | G34: =IF(G28=0,0,G32/G28) -> 0.21055684 | H34: =IF(G34>=0.2,"🌟 Excellent","👍 Keep Going") -> 🌟 Excellent
B36: 💰 REMAINING BALANCE This Month | G36: =G33 -> 20500 | O36: =IF(G33>=0,"✅ You're on track!","⚠️ You've overspent") -> ✅ You're on track!
B41: 💡 Tip: Blue numbers are editable inputs. Black text & percentages auto-calculate — nothing else needs to be touched.
B42: ✨ Premium Budget Tracker 2026 ✨

Sheet Aug
B1: 🏠 DASHBOARD | F1: ✨ PREMIUM MONTHLY BUDGET TRACKER ✨ | N1: ◀ Jul | R1: Sep ▶
B2: 🌻 AUGUST
B3: Monthly Budget Tracker • Edit only the blue input cells
B5: 💵 TOTAL INCOME | G5: 🧾 TOTAL EXPENSES | L5: 💎 TOTAL SAVINGS | Q5: ⚖️ NET BALANCE
B7: =G28 -> 76200 | G7: =G31 -> 47737 | L7: =G32 -> 16507 | Q7: =G33 -> 11956
B10: 💵 INCOME | G10: 🏠 FIXED EXPENSES (Bills + EMIs) | L10: 🛍️ VARIABLE EXPENSES | Q10: 💎 SAVINGS & INVESTMENTS
B11: Category | C11: Planned | D11: Actual | E11: Progress | G11: Category | H11: Planned | I11: Actual | J11: Progress | L11: Category | M11: Planned | N11: Actual | O11: Progress | Q11: Category | R11: Planned | S11: Actual | T11: Progress
B12: 💼 Salary / Full-time Job | C12: 69000 | D12: 69000 | E12: =IF(C12=0,IF(D12=0,0,1),D12/C12) -> 1 | G12: 🏠 Rent / Home Loan EMI | H12: 15000 | I12: 15375 | J12: =IF(H12=0,IF(I12=0,0,1),I12/H12) -> 1.025 | L12: 🛒 Groceries | M12: 6000 | N12: 6060 | O12: =IF(M12=0,IF(N12=0,0,1),N12/M12) -> 1.01 | Q12: 🚨 Emergency Fund | R12: 3000 | S12: 2955 | T12: =IF(R12=0,IF(S12=0,0,1),S12/R12) -> 0.985
B13: 🧑‍💻 Freelance / Side Hustle | C13: 6000 | D13: 6000 | E13: =IF(C13=0,IF(D13=0,0,1),D13/C13) -> 1 | G13: 💡 Electricity Bill | H13: 2420 | I13: 2432 | J13: =IF(H13=0,IF(I13=0,0,1),I13/H13) -> 1.0049587 | L13: 🍽️ Eating Out / Dining | M13: 2500 | N13: 2425 | O13: =IF(M13=0,IF(N13=0,0,1),N13/M13) -> 0.97 | Q13: 📊 Mutual Fund / SIP | R13: 5000 | S13: 5100 | T13: =IF(R13=0,IF(S13=0,0,1),S13/R13) -> 1.02
B14: 🏢 Business Income | C14: 0 | D14: 0 | E14: =IF(C14=0,IF(D14=0,0,1),D14/C14) -> 0 | G14: 🚰 Water Bill | H14: 300 | I14: 296 | J14: =IF(H14=0,IF(I14=0,0,1),I14/H14) -> 0.98666667 | L14: ⛽ Transport / Fuel | M14: 2000 | N14: 2080 | O14: =IF(M14=0,IF(N14=0,0,1),N14/M14) -> 1.04 | Q14: 🏦 PPF / EPF | R14: 2000 | S14: 2000 | T14: =IF(R14=0,IF(S14=0,0,1),S14/R14) -> 1
B15: 🏠 Rental Income | C15: 0 | D15: 0 | E15: =IF(C15=0,IF(D15=0,0,1),D15/C15) -> 0 | G15: 🌐 Internet / WiFi | H15: 800 | I15: 816 | J15: =IF(H15=0,IF(I15=0,0,1),I15/H15) -> 1.02 | L15: 🛍️ Shopping / Clothing | M15: 3000 | N15: 3000 | O15: =IF(M15=0,IF(N15=0,0,1),N15/M15) -> 1 | Q15: 🥇 Stocks / Gold | R15: 1000 | S15: 980 | T15: =IF(R15=0,IF(S15=0,0,1),S15/R15) -> 0.98
B16: 📈 Investment Returns | C16: 1200 | D16: 1200 | E16: =IF(C16=0,IF(D16=0,0,1),D16/C16) -> 1 | G16: 📱 Mobile Recharge | H16: 400 | I16: 400 | J16: =IF(H16=0,IF(I16=0,0,1),I16/H16) -> 1 | L16: 🎮 Entertainment | M16: 1000 | N16: 960 | O16: =IF(M16=0,IF(N16=0,0,1),N16/M16) -> 0.96 | Q16: 🔒 Fixed Deposit / RD | R16: 2000 | S16: 2030 | T16: =IF(R16=0,IF(S16=0,0,1),S16/R16) -> 1.015
B17: 🎁 Bonus / Incentive | C17: 0 | D17: 0 | E17: =IF(C17=0,IF(D17=0,0,1),D17/C17) -> 0 | G17: 🛡️ Insurance Premium | H17: 1200 | I17: 1176 | J17: =IF(H17=0,IF(I17=0,0,1),I17/H17) -> 0.98 | L17: 💇 Personal Care | M17: 800 | N17: 824 | O17: =IF(M17=0,IF(N17=0,0,1),N17/M17) -> 1.03 | Q17: 👴 Retirement (NPS) | R17: 1500 | S17: 1492 | T17: =IF(R17=0,IF(S17=0,0,1),S17/R17) -> 0.99466667
B18: ➕ Other Income 1 | C18: 0 | D18: 0 | E18: =IF(C18=0,IF(D18=0,0,1),D18/C18) -> 0 | G18: 🚗 Car / Vehicle EMI | H18: 6000 | I18: 6090 | J18: =IF(H18=0,IF(I18=0,0,1),I18/H18) -> 1.015 | L18: 🏥 Health / Medical | M18: 1000 | N18: 990 | O18: =IF(M18=0,IF(N18=0,0,1),N18/M18) -> 0.99 | Q18: 🎯 Goal-based Savings | R18: 2000 | S18: 1950 | T18: =IF(R18=0,IF(S18=0,0,1),S18/R18) -> 0.975
B19: ➕ Other Income 2 | C19: 0 | D19: 0 | E19: =IF(C19=0,IF(D19=0,0,1),D19/C19) -> 0 | G19: 🎬 OTT Subscriptions | H19: 500 | I19: 498 | J19: =IF(H19=0,IF(I19=0,0,1),I19/H19) -> 0.996 | L19: 📚 Education / Courses | M19: 0 | N19: 0 | O19: =IF(M19=0,IF(N19=0,0,1),N19/M19) -> 0 | Q19: ➕ Other Savings | R19: 0 | S19: 0 | T19: =IF(R19=0,IF(S19=0,0,1),S19/R19) -> 0
B20: TOTAL | C20: =SUM(C12:C19) -> 76200 | D20: =SUM(D12:D19) -> 76200 | E20: =IF(C20=0,IF(D20=0,0,1),D20/C20) -> 1 | G20: 🏢 Society / Maintenance | H20: 1500 | I20: 1462 | J20: =IF(H20=0,IF(I20=0,0,1),I20/H20) -> 0.97466667 | L20: ✈️ Travel / Vacation | M20: 1500 | N20: 1530 | O20: =IF(M20=0,IF(N20=0,0,1),N20/M20) -> 1.02 | Q20: TOTAL | R20: =SUM(R12:R19) -> 16500 | S20: =SUM(S12:S19) -> 16507 | T20: =IF(R20=0,IF(S20=0,0,1),S20/R20) -> 1.0004242
G21: ➕ Other Fixed Expense | H21: 0 | I21: 0 | J21: =IF(H21=0,IF(I21=0,0,1),I21/H21) -> 0 | L21: 🎀 Gifts & Donations | M21: 600 | N21: 588 | O21: =IF(M21=0,IF(N21=0,0,1),N21/M21) -> 0.98
G22: TOTAL | H22: =SUM(H12:H21) -> 28120 | I22: =SUM(I12:I21) -> 28545 | J22: =IF(H22=0,IF(I22=0,0,1),I22/H22) -> 1.0151138 | L22: 🧺 Household Items | M22: 700 | N22: 735 | O22: =IF(M22=0,IF(N22=0,0,1),N22/M22) -> 1.05
L23: ➕ Other Variable Expense | M23: 0 | N23: 0 | O23: =IF(M23=0,IF(N23=0,0,1),N23/M23) -> 0
L24: TOTAL | M24: =SUM(M12:M23) -> 19100 | N24: =SUM(N12:N23) -> 19192 | O24: =IF(M24=0,IF(N24=0,0,1),N24/M24) -> 1.0048168
B26: 📊 MONTHLY SUMMARY
B27: Metric | F27: Planned | G27: Actual | H27: Status
B28: 💵 Total Income | F28: =C20 -> 76200 | G28: =D20 -> 76200 | H28: =IF(G28>=F28,"✅ Goal Met","⚠️ Below Target") -> ✅ Goal Met
B29: 🏠 Total Fixed Expenses | F29: =H22 -> 28120 | G29: =I22 -> 28545 | H29: =IF(G29>F29,"⚠️ Over Budget","✅ On Budget") -> ⚠️ Over Budget
B30: 🛍️ Total Variable Expenses | F30: =M24 -> 19100 | G30: =N24 -> 19192 | H30: =IF(G30>F30,"⚠️ Over Budget","✅ On Budget") -> ⚠️ Over Budget
B31: 🧾 Total Expenses (Fixed + Variable) | F31: =F29+F30 -> 47220 | G31: =G29+G30 -> 47737 | H31: =IF(G31>F31,"⚠️ Over Budget","✅ On Budget") -> ⚠️ Over Budget
B32: 💎 Total Savings & Investments | F32: =R20 -> 16500 | G32: =S20 -> 16507 | H32: =IF(G32>=F32,"✅ Goal Met","⚠️ Below Goal") -> ✅ Goal Met
B33: ⚖️ Remaining Balance | F33: =F28-F31-F32 -> 12480 | G33: =G28-G31-G32 -> 11956 | H33: =IF(G33>=0,"✅ Surplus","⚠️ Deficit") -> ✅ Surplus
B34: 📈 Savings Rate (Savings ÷ Income) | F34: =IF(F28=0,0,F32/F28) -> 0.21653543 | G34: =IF(G28=0,0,G32/G28) -> 0.2166273 | H34: =IF(G34>=0.2,"🌟 Excellent","👍 Keep Going") -> 🌟 Excellent
B36: 💰 REMAINING BALANCE This Month | G36: =G33 -> 11956 | O36: =IF(G33>=0,"✅ You're on track!","⚠️ You've overspent") -> ✅ You're on track!
B41: 💡 Tip: Blue numbers are editable inputs. Black text & percentages auto-calculate — nothing else needs to be touched.
B42: ✨ Premium Budget Tracker 2026 ✨

Sheet Sep
B1: 🏠 DASHBOARD | F1: ✨ PREMIUM MONTHLY BUDGET TRACKER ✨ | N1: ◀ Aug | R1: Oct ▶
B2: 🍃 SEPTEMBER
B3: Monthly Budget Tracker • Edit only the blue input cells
B5: 💵 TOTAL INCOME | G5: 🧾 TOTAL EXPENSES | L5: 💎 TOTAL SAVINGS | Q5: ⚖️ NET BALANCE
B7: =G28 -> 76200 | G7: =G31 -> 47010 | L7: =G32 -> 16397 | Q7: =G33 -> 12793
B10: 💵 INCOME | G10: 🏠 FIXED EXPENSES (Bills + EMIs) | L10: 🛍️ VARIABLE EXPENSES | Q10: 💎 SAVINGS & INVESTMENTS
B11: Category | C11: Planned | D11: Actual | E11: Progress | G11: Category | H11: Planned | I11: Actual | J11: Progress | L11: Category | M11: Planned | N11: Actual | O11: Progress | Q11: Category | R11: Planned | S11: Actual | T11: Progress
B12: 💼 Salary / Full-time Job | C12: 69000 | D12: 69000 | E12: =IF(C12=0,IF(D12=0,0,1),D12/C12) -> 1 | G12: 🏠 Rent / Home Loan EMI | H12: 15000 | I12: 14700 | J12: =IF(H12=0,IF(I12=0,0,1),I12/H12) -> 0.98 | L12: 🛒 Groceries | M12: 6000 | N12: 6180 | O12: =IF(M12=0,IF(N12=0,0,1),N12/M12) -> 1.03 | Q12: 🚨 Emergency Fund | R12: 3000 | S12: 2985 | T12: =IF(R12=0,IF(S12=0,0,1),S12/R12) -> 0.995
B13: 🧑‍💻 Freelance / Side Hustle | C13: 6000 | D13: 6000 | E13: =IF(C13=0,IF(D13=0,0,1),D13/C13) -> 1 | G13: 💡 Electricity Bill | H13: 2200 | I13: 2233 | J13: =IF(H13=0,IF(I13=0,0,1),I13/H13) -> 1.015 | L13: 🍽️ Eating Out / Dining | M13: 2500 | N13: 2475 | O13: =IF(M13=0,IF(N13=0,0,1),N13/M13) -> 0.99 | Q13: 📊 Mutual Fund / SIP | R13: 5000 | S13: 4875 | T13: =IF(R13=0,IF(S13=0,0,1),S13/R13) -> 0.975
B14: 🏢 Business Income | C14: 0 | D14: 0 | E14: =IF(C14=0,IF(D14=0,0,1),D14/C14) -> 0 | G14: 🚰 Water Bill | H14: 300 | I14: 298 | J14: =IF(H14=0,IF(I14=0,0,1),I14/H14) -> 0.99333333 | L14: ⛽ Transport / Fuel | M14: 2000 | N14: 1900 | O14: =IF(M14=0,IF(N14=0,0,1),N14/M14) -> 0.95 | Q14: 🏦 PPF / EPF | R14: 2000 | S14: 2020 | T14: =IF(R14=0,IF(S14=0,0,1),S14/R14) -> 1.01
B15: 🏠 Rental Income | C15: 0 | D15: 0 | E15: =IF(C15=0,IF(D15=0,0,1),D15/C15) -> 0 | G15: 🌐 Internet / WiFi | H15: 800 | I15: 780 | J15: =IF(H15=0,IF(I15=0,0,1),I15/H15) -> 0.975 | L15: 🛍️ Shopping / Clothing | M15: 3000 | N15: 3060 | O15: =IF(M15=0,IF(N15=0,0,1),N15/M15) -> 1.02 | Q15: 🥇 Stocks / Gold | R15: 1000 | S15: 990 | T15: =IF(R15=0,IF(S15=0,0,1),S15/R15) -> 0.99
B16: 📈 Investment Returns | C16: 1200 | D16: 1200 | E16: =IF(C16=0,IF(D16=0,0,1),D16/C16) -> 1 | G16: 📱 Mobile Recharge | H16: 400 | I16: 404 | J16: =IF(H16=0,IF(I16=0,0,1),I16/H16) -> 1.01 | L16: 🎮 Entertainment | M16: 1000 | N16: 980 | O16: =IF(M16=0,IF(N16=0,0,1),N16/M16) -> 0.98 | Q16: 🔒 Fixed Deposit / RD | R16: 2000 | S16: 2050 | T16: =IF(R16=0,IF(S16=0,0,1),S16/R16) -> 1.025
B17: 🎁 Bonus / Incentive | C17: 0 | D17: 0 | E17: =IF(C17=0,IF(D17=0,0,1),D17/C17) -> 0 | G17: 🛡️ Insurance Premium | H17: 1200 | I17: 1188 | J17: =IF(H17=0,IF(I17=0,0,1),I17/H17) -> 0.99 | L17: 💇 Personal Care | M17: 800 | N17: 840 | O17: =IF(M17=0,IF(N17=0,0,1),N17/M17) -> 1.05 | Q17: 👴 Retirement (NPS) | R17: 1500 | S17: 1507 | T17: =IF(R17=0,IF(S17=0,0,1),S17/R17) -> 1.0046667
B18: ➕ Other Income 1 | C18: 0 | D18: 0 | E18: =IF(C18=0,IF(D18=0,0,1),D18/C18) -> 0 | G18: 🚗 Car / Vehicle EMI | H18: 6000 | I18: 6150 | J18: =IF(H18=0,IF(I18=0,0,1),I18/H18) -> 1.025 | L18: 🏥 Health / Medical | M18: 1000 | N18: 1010 | O18: =IF(M18=0,IF(N18=0,0,1),N18/M18) -> 1.01 | Q18: 🎯 Goal-based Savings | R18: 2000 | S18: 1970 | T18: =IF(R18=0,IF(S18=0,0,1),S18/R18) -> 0.985
B19: ➕ Other Income 2 | C19: 0 | D19: 0 | E19: =IF(C19=0,IF(D19=0,0,1),D19/C19) -> 0 | G19: 🎬 OTT Subscriptions | H19: 500 | I19: 502 | J19: =IF(H19=0,IF(I19=0,0,1),I19/H19) -> 1.004 | L19: 📚 Education / Courses | M19: 0 | N19: 0 | O19: =IF(M19=0,IF(N19=0,0,1),N19/M19) -> 0 | Q19: ➕ Other Savings | R19: 0 | S19: 0 | T19: =IF(R19=0,IF(S19=0,0,1),S19/R19) -> 0
B20: TOTAL | C20: =SUM(C12:C19) -> 76200 | D20: =SUM(D12:D19) -> 76200 | E20: =IF(C20=0,IF(D20=0,0,1),D20/C20) -> 1 | G20: 🏢 Society / Maintenance | H20: 1500 | I20: 1478 | J20: =IF(H20=0,IF(I20=0,0,1),I20/H20) -> 0.98533333 | L20: ✈️ Travel / Vacation | M20: 1500 | N20: 1560 | O20: =IF(M20=0,IF(N20=0,0,1),N20/M20) -> 1.04 | Q20: TOTAL | R20: =SUM(R12:R19) -> 16500 | S20: =SUM(S12:S19) -> 16397 | T20: =IF(R20=0,IF(S20=0,0,1),S20/R20) -> 0.99375758
G21: ➕ Other Fixed Expense | H21: 0 | I21: 0 | J21: =IF(H21=0,IF(I21=0,0,1),I21/H21) -> 0 | L21: 🎀 Gifts & Donations | M21: 600 | N21: 600 | O21: =IF(M21=0,IF(N21=0,0,1),N21/M21) -> 1
G22: TOTAL | H22: =SUM(H12:H21) -> 27900 | I22: =SUM(I12:I21) -> 27733 | J22: =IF(H22=0,IF(I22=0,0,1),I22/H22) -> 0.99401434 | L22: 🧺 Household Items | M22: 700 | N22: 672 | O22: =IF(M22=0,IF(N22=0,0,1),N22/M22) -> 0.96
L23: ➕ Other Variable Expense | M23: 0 | N23: 0 | O23: =IF(M23=0,IF(N23=0,0,1),N23/M23) -> 0
L24: TOTAL | M24: =SUM(M12:M23) -> 19100 | N24: =SUM(N12:N23) -> 19277 | O24: =IF(M24=0,IF(N24=0,0,1),N24/M24) -> 1.009267
B26: 📊 MONTHLY SUMMARY
B27: Metric | F27: Planned | G27: Actual | H27: Status
B28: 💵 Total Income | F28: =C20 -> 76200 | G28: =D20 -> 76200 | H28: =IF(G28>=F28,"✅ Goal Met","⚠️ Below Target") -> ✅ Goal Met
B29: 🏠 Total Fixed Expenses | F29: =H22 -> 27900 | G29: =I22 -> 27733 | H29: =IF(G29>F29,"⚠️ Over Budget","✅ On Budget") -> ✅ On Budget
B30: 🛍️ Total Variable Expenses | F30: =M24 -> 19100 | G30: =N24 -> 19277 | H30: =IF(G30>F30,"⚠️ Over Budget","✅ On Budget") -> ⚠️ Over Budget
B31: 🧾 Total Expenses (Fixed + Variable) | F31: =F29+F30 -> 47000 | G31: =G29+G30 -> 47010 | H31: =IF(G31>F31,"⚠️ Over Budget","✅ On Budget") -> ⚠️ Over Budget
B32: 💎 Total Savings & Investments | F32: =R20 -> 16500 | G32: =S20 -> 16397 | H32: =IF(G32>=F32,"✅ Goal Met","⚠️ Below Goal") -> ⚠️ Below Goal
B33: ⚖️ Remaining Balance | F33: =F28-F31-F32 -> 12700 | G33: =G28-G31-G32 -> 12793 | H33: =IF(G33>=0,"✅ Surplus","⚠️ Deficit") -> ✅ Surplus
B34: 📈 Savings Rate (Savings ÷ Income) | F34: =IF(F28=0,0,F32/F28) -> 0.21653543 | G34: =IF(G28=0,0,G32/G28) -> 0.21518373 | H34: =IF(G34>=0.2,"🌟 Excellent","👍 Keep Going") -> 🌟 Excellent
B36: 💰 REMAINING BALANCE This Month | G36: =G33 -> 12793 | O36: =IF(G33>=0,"✅ You're on track!","⚠️ You've overspent") -> ✅ You're on track!
B41: 💡 Tip: Blue numbers are editable inputs. Black text & percentages auto-calculate — nothing else needs to be touched.
B42: ✨ Premium Budget Tracker 2026 ✨

Sheet Oct
B1: 🏠 DASHBOARD | F1: ✨ PREMIUM MONTHLY BUDGET TRACKER ✨ | N1: ◀ Sep | R1: Nov ▶
B2: 🎆 OCTOBER
B3: Monthly Budget Tracker • Edit only the blue input cells
B5: 💵 TOTAL INCOME | G5: 🧾 TOTAL EXPENSES | L5: 💎 TOTAL SAVINGS | Q5: ⚖️ NET BALANCE
B7: =G28 -> 83200 | G7: =G31 -> 61539 | L7: =G32 -> 9075 | Q7: =G33 -> 12586
B10: 💵 INCOME | G10: 🏠 FIXED EXPENSES (Bills + EMIs) | L10: 🛍️ VARIABLE EXPENSES | Q10: 💎 SAVINGS & INVESTMENTS
B11: Category | C11: Planned | D11: Actual | E11: Progress | G11: Category | H11: Planned | I11: Actual | J11: Progress | L11: Category | M11: Planned | N11: Actual | O11: Progress | Q11: Category | R11: Planned | S11: Actual | T11: Progress
B12: 💼 Salary / Full-time Job | C12: 71000 | D12: 71000 | E12: =IF(C12=0,IF(D12=0,0,1),D12/C12) -> 1 | G12: 🏠 Rent / Home Loan EMI | H12: 15000 | I12: 14850 | J12: =IF(H12=0,IF(I12=0,0,1),I12/H12) -> 0.99 | L12: 🛒 Groceries | M12: 6000 | N12: 7380 | O12: =IF(M12=0,IF(N12=0,0,1),N12/M12) -> 1.23 | Q12: 🚨 Emergency Fund | R12: 3000 | S12: 1650 | T12: =IF(R12=0,IF(S12=0,0,1),S12/R12) -> 0.55
B13: 🧑‍💻 Freelance / Side Hustle | C13: 6000 | D13: 6000 | E13: =IF(C13=0,IF(D13=0,0,1),D13/C13) -> 1 | G13: 💡 Electricity Bill | H13: 2200 | I13: 2255 | J13: =IF(H13=0,IF(I13=0,0,1),I13/H13) -> 1.025 | L13: 🍽️ Eating Out / Dining | M13: 3250 | N13: 3868 | O13: =IF(M13=0,IF(N13=0,0,1),N13/M13) -> 1.1901538 | Q13: 📊 Mutual Fund / SIP | R13: 5000 | S13: 2750 | T13: =IF(R13=0,IF(S13=0,0,1),S13/R13) -> 0.55
B14: 🏢 Business Income | C14: 0 | D14: 0 | E14: =IF(C14=0,IF(D14=0,0,1),D14/C14) -> 0 | G14: 🚰 Water Bill | H14: 300 | I14: 301 | J14: =IF(H14=0,IF(I14=0,0,1),I14/H14) -> 1.0033333 | L14: ⛽ Transport / Fuel | M14: 2000 | N14: 2300 | O14: =IF(M14=0,IF(N14=0,0,1),N14/M14) -> 1.15 | Q14: 🏦 PPF / EPF | R14: 2000 | S14: 1100 | T14: =IF(R14=0,IF(S14=0,0,1),S14/R14) -> 0.55
B15: 🏠 Rental Income | C15: 0 | D15: 0 | E15: =IF(C15=0,IF(D15=0,0,1),D15/C15) -> 0 | G15: 🌐 Internet / WiFi | H15: 800 | I15: 788 | J15: =IF(H15=0,IF(I15=0,0,1),I15/H15) -> 0.985 | L15: 🛍️ Shopping / Clothing | M15: 7800 | N15: 9516 | O15: =IF(M15=0,IF(N15=0,0,1),N15/M15) -> 1.22 | Q15: 🥇 Stocks / Gold | R15: 1000 | S15: 550 | T15: =IF(R15=0,IF(S15=0,0,1),S15/R15) -> 0.55
B16: 📈 Investment Returns | C16: 1200 | D16: 1200 | E16: =IF(C16=0,IF(D16=0,0,1),D16/C16) -> 1 | G16: 📱 Mobile Recharge | H16: 400 | I16: 408 | J16: =IF(H16=0,IF(I16=0,0,1),I16/H16) -> 1.02 | L16: 🎮 Entertainment | M16: 1000 | N16: 1180 | O16: =IF(M16=0,IF(N16=0,0,1),N16/M16) -> 1.18 | Q16: 🔒 Fixed Deposit / RD | R16: 2000 | S16: 1100 | T16: =IF(R16=0,IF(S16=0,0,1),S16/R16) -> 0.55
B17: 🎁 Bonus / Incentive | C17: 5000 | D17: 5000 | E17: =IF(C17=0,IF(D17=0,0,1),D17/C17) -> 1 | G17: 🛡️ Insurance Premium | H17: 1200 | I17: 1200 | J17: =IF(H17=0,IF(I17=0,0,1),I17/H17) -> 1 | L17: 💇 Personal Care | M17: 800 | N17: 912 | O17: =IF(M17=0,IF(N17=0,0,1),N17/M17) -> 1.14 | Q17: 👴 Retirement (NPS) | R17: 1500 | S17: 825 | T17: =IF(R17=0,IF(S17=0,0,1),S17/R17) -> 0.55
